Workbook

Sheet Cover
A1: Discounted Cash Flow Model (DCF Model)
A2: Company name | B2: *ST天沃 | C2: Code | D2: 002564
A3: Latest reporting date | B3: 44561 | C3: Share price at Latest reporting date | D3: 4.74
A4: N | B4: =YEAR(B3) -> 2021 | C4: Total shares at Latest reporting date | D4: 869375282
A6: To simplify, assume valuation date is latest reporting date

Sheet BS_ORIG
C1: N-5 | D1: N-4 | E1: N-3 | F1: N-2 | G1: N-1 | H1: N
B2: Balance Sheet | C2: 2016 | D2: 2017 | E2: 2018 | F2: 2019 | G2: 2020 | H2: 2021
A3: a001101000 | B3: Cash and cash equivalents | C3: 1.5924445e+09 | D3: 1.3255263e+09 | E3: 2.2799954e+09 | F3: 2.5525243e+09 | G3: 2.2643564e+09 | H3: 1.4634375e+09
A4: a001107000 | B4: Trading Financial Assets | F4: 13461708
A5: a001109000 | B5: Net Short-term Investments
A6: a001110000 | B6: Net Notes Receivable | C6: 4.1951078e+08 | D6: 1.8349088e+09 | E6: 3.134285e+08 | F6: 65026761 | G6: 1.2313417e+08 | H6: 3.7457385e+08
A7: a001111000 | B7: Net Accounts Receivable | C7: 3.6891334e+09 | D7: 4.8452735e+09 | E7: 7.4626518e+09 | F7: 6.7934111e+09 | G7: 6.23888e+09 | H7: 4.5219054e+09
A8: a001123000 | B8: Net Inventories | C8: 5.19858e+09 | D8: 7.4392013e+09 | E8: 7.1135823e+09 | F8: 2.9086657e+09 | G8: 1.9140471e+09 | H8: 1.8662541e+09
A9: a001100000 | B9: Total current assets | C9: 1.1960647e+10 | D9: 17454797991 | E9: 1.9910884e+10 | F9: 2.537087e+10 | G9: 2.4328693e+10 | H9: 2.2146279e+10
A10: a001212000 | B10: Net Fixed Assets | C10: 1.9680651e+09 | D10: 1.8367497e+09 | E10: 1.7293135e+09 | F10: 1.4216552e+09 | G10: 1.3043049e+09 | H10: 1.2368576e+09
A11: a001218000 | B11: Net Intangible Assets | C11: 3.6853816e+08 | D11: 2.7100475e+08 | E11: 2.5111901e+08 | F11: 2.1482327e+08 | G11: 1.951898e+08 | H11: 1.8835227e+08
A12: a001200000 | B12: Total Non-current Assets | C12: 5.0441884e+09 | D12: 5.1319195e+09 | E12: 5.9538674e+09 | F12: 6.4552434e+09 | G12: 6.0592021e+09 | H12: 6.326076e+09
A13: a001000000 | B13: Total Assets | C13: 1.7004836e+10 | D13: 2.2586717e+10 | E13: 2.5864752e+10 | F13: 3.1826113e+10 | G13: 3.0387895e+10 | H13: 2.8472355e+10
A14: a002101000 | B14: Short-Term Borrowings | C14: 2.3983231e+09 | D14: 3.0195183e+09 | E14: 6847020000 | F14: 6269244000 | G14: 5.3057837e+09 | H14: 4694800000
A15: a002107000 | B15: Notes Payable | C15: 7.402711e+08 | D15: 7.8965515e+08 | E15: 1.7649862e+09 | F15: 1.0684524e+09 | G15: 1.1210335e+09 | H15: 3.7066576e+08
A16: a002108000 | B16: Accounts Payable | C16: 4.2743978e+09 | D16: 6.7426092e+09 | E16: 5.974537e+09 | F16: 9.591968e+09 | G16: 8.7048753e+09 | H16: 9.2298704e+09
A17: a002100000 | B17: Total Current Liabilities | C17: 1.0159178e+10 | D17: 1.5712893e+10 | E17: 2.0106942e+10 | F17: 2.2634928e+10 | G17: 2.2345065e+10 | H17: 2.2473239e+10
... A23: a003000000 | B23: Total Shareholders' Equity | C23: 2.7806264e+09 | D23: 3.1598283e+09 | E23: 4.3572856e+09 | F23: 4.4989964e+09 | G23: 3.0864771e+09 | H23: 2.2372606e+09

Sheet IS_ORIG
C1: N-5 | D1: N-4 | E1: N-3 | F1: N-2 | G1: N-1 | H1: N
B2: Income Statement | C2: 2016 | D2: 2017 | E2: 2018 | F2: 2019 | G2: 2020 | H2: 2021
A3: b001101000 | B3: Operating Revenue | C3: 1.1951452e+09 | D3: 1.0403684e+10 | E3: 7.7001635e+09 | F3: 1.0779197e+10 | G3: 7.7124736e+09 | H3: 6.8067912e+09
A4: b001201000 | B4: Operating Expenses | C4: 9.7983838e+08 | D4: 9.2813995e+09 | E4: 6.5582098e+09 | F4: 9.2800606e+09 | G4: 7.6896156e+09 | H4: 5.6706337e+09
A5: b001207000 | B5: Tax And Additional Fees Of Operations | C5: 20190136 | D5: 36205192 | E5: 26398820 | F5: 31703523 | G5: 31857634 | H5: 30964087
A6: b001209000 | B6: Selling Expenses | C6: 39772376 | D6: 89749952 | E6: 57561291 | F6: 67563388 | G6: 44459026 | H6: 45204394
A7: b001210000 | B7: General And Administrative Expenses | C7: 2.3282551e+08 | D7: 3.2137726e+08 | E7: 2.7620403e+08 | F7: 2.5651067e+08 | G7: 2.2701737e+08 | H7: 1.9714701e+08
A8: b001216000 | B8: R&D Expenses | E8: 80886178 | F8: 1.0032732e+08 | G8: 2.8492251e+08 | H8: 2.4277138e+08
A9: b001302000 | B9: Investment Gains | C9: -1948003.4 | D9: 1.3407863e+08 | E9: 88534509 | F9: -1.3235346e+08 | G9: 78508508 | H9: 79056432
A10: b001212000 | B10: Asset Impairment Loss | C10: 97519459 | D10: 1.0144876e+08 | E10: 2.5506934e+08 | F10: -30526832 | G10: -2.5716226e+08 | H10: -3.5989022e+08
A11: b001307000 | B11: Credit impairment loss | F11: -1.8133298e+08 | G11: -4.5279544e+08 | H11: -7.2544433e+08
A12: b001301000 | B12: Gains/Losses From Fair Value Change | F12: 0
A13: b001308000 | B13: Income from Assets Disposal | D13: 3946601 | E13: -1576500.1 | F13: 1439776 | G13: 19545451 | H13: 1815179.8
A14: b001211000 | B14: Finance Expenses | C14: 1.8309135e+08 | D14: 4.4675826e+08 | E14: 3.3252099e+08 | F14: 5.0139254e+08 | G14: 5.1215073e+08 | H14: 4.8408467e+08
A15: b001211101 | B15: Including: Interest Expenses | E15: 3.0102171e+08 | F15: 4.8974373e+08 | G15: 5.1232358e+08 | H15: 4.8683431e+08
A16: b001211203 | B16: Including: Interest Income | E16: 2782474.2 | F16: 29324587 | G16: 22173471 | H16: 10913197
A17: b001300000 | B17: Operating Profit | C17: -3.6003997e+08 | D17: 2.7591308e+08 | E17: 2.1040982e+08 | F17: 2.131555e+08 | G17: -1.6704093e+09 | H17: -8.5550241e+08
A18: b001400000 | B18: Non-Operating Income | C18: 24882166 | D18: 6646149.8 | E18: 3367168.8 | F18: 2548028.2 | G18: 3743923.5 | H18: 4236590.8
A19: b001500000 | B19: Non-Operating Expenses | C19: 8198986.8 | D19: 15357876 | E19: 12274754 | F19: 39338765 | G19: 8174686.7 | H19: 6716739.2
A20: b001000000 | B20: Total Profit | C20: -3.433568e+08 | D20: 2.6720136e+08 | E20: 2.0150224e+08 | F20: 1.7636476e+08 | G20: -1.6748401e+09 | H20: -8.5798256e+08
A21: b002100000 | B21: Income Tax Expenses | C21: -37460937 | D21: -53315272 | E21: 16014110 | F21: 37524520 | G21: -2.7291958e+08 | H21: -34739082
A22: b002000000 | B22: Net Profit | C22: -3.0589586e+08 | D22: 3.2051663e+08 | E22: 1.8548813e+08 | F22: 1.3884024e+08 | G22: -1.4019205e+09 | H22: -8.2324348e+08
A23: b002000101 | B23: Net Profit Attributable To Owners Of The Parent Company | C23: -2.9971088e+08 | D23: 2.2514558e+08 | E23: 74602747 | F23: 42391861 | G23: -1.1595173e+09 | H23: -6.9331976e+08

Sheet BS
B1: N-5 | C1: N-4 | D1: N-3 | E1: N-2 | F1: N-1 | G1: N | H1: N+1E | I1: N+2E | J1: N+3E | K1: N+4E | L1: N+5E
B2: 2016 | C2: 2017 | D2: 2018 | E2: 2019 | F2: 2020 | G2: 2021 | H2: 2022 | I2: 2023 | J2: 2024 | K2: 2025 | L2: 2026
A3: Cash and equivalent | B3: =SUM(BS_ORIG!C3:C5) -> 1.5924445e+09 | C3: =SUM(BS_ORIG!D3:D5) -> 1.3255263e+09 | D3: =SUM(BS_ORIG!E3:E5) -> 2.2799954e+09 | E3: =SUM(BS_ORIG!F3:F5) -> 2.565986e+09 | F3: =SUM(BS_ORIG!G3:G5) -> 2.2643564e+09 | G3: =SUM(BS_ORIG!H3:H5) -> 1.4634375e+09 | H3: =H29-H12-SUM(H4:H6) -> 3.7685937e+08 | I3: =I29-I12-SUM(I4:I6) -> -4.4961741e+08 | J3: =J29-J12-SUM(J4:J6) -> -1.0529074e+09 | K3: =K29-K12-SUM(K4:K6) -> -1.8643134e+09 | L3: =L29-L12-SUM(L4:L6) -> -2.6229964e+09
A4: Notes and accounts receivable | B4: =SUM(BS_ORIG!C6:C7) -> 4.1086442e+09 | C4: =SUM(BS_ORIG!D6:D7) -> 6.6801824e+09 | D4: =SUM(BS_ORIG!E6:E7) -> 7.7760803e+09 | E4: =SUM(BS_ORIG!F6:F7) -> 6.8584379e+09 | F4: =SUM(BS_ORIG!G6:G7) -> 6.3620141e+09 | G4: =SUM(BS_ORIG!H6:H7) -> 4.8964792e+09 | H4: =Assumption!G15*IS!H3 -> 4.8757234e+09 | I4: =Assumption!H15*IS!I3 -> 4.9489698e+09 | J4: =Assumption!I15*IS!J3 -> 4.1095877e+09 | K4: =Assumption!J15*IS!K3 -> 3.8925679e+09 | L4: =Assumption!K15*IS!L3 -> 3.5649098e+09
A5: Inventory | B5: =SUM(BS_ORIG!C8:C8) -> 5.19858e+09 | C5: =SUM(BS_ORIG!D8:D8) -> 7.4392013e+09 | D5: =SUM(BS_ORIG!E8:E8) -> 7.1135823e+09 | E5: =SUM(BS_ORIG!F8:F8) -> 2.9086657e+09 | F5: =SUM(BS_ORIG!G8:G8) -> 1.9140471e+09 | G5: =SUM(BS_ORIG!H8:H8) -> 1.8662541e+09 | H5: =Assumption!G16*IS!H3 -> 3.0928364e+09 | I5: =Assumption!H16*IS!I3 -> 2.7543874e+09 | J5: =Assumption!I16*IS!J3 -> 1.8895229e+09 | K5: =Assumption!J16*IS!K3 -> 1.8126973e+09 | L5: =Assumption!K16*IS!L3 -> 1.7878391e+09
A6: Total other current assets | B6: =B7-SUM(B3:B5) -> 1.0609785e+09 | C6: =C7-SUM(C3:C5) -> 2.009888e+09 | D6: =D7-SUM(D3:D5) -> 2.7412265e+09 | E6: =E7-SUM(E3:E5) -> 1.303778e+10 | F6: =F7-SUM(F3:F5) -> 1.3788276e+10 | G6: =G7-SUM(G3:G5) -> 1.3920109e+10 | H6: =Assumption!G17*IS!H3 -> 7.1136281e+09 | I6: =Assumption!H17*IS!I3 -> 8.1505649e+09 | J6: =Assumption!I17*IS!J3 -> 8.2051252e+09 | K6: =Assumption!J17*IS!K3 -> 7.8333287e+09 | L6: =Assumption!K17*IS!L3 -> 7.0539208e+09
A7: Total current assets | B7: =BS_ORIG!C9 -> 1.1960647e+10 | C7: =BS_ORIG!D9 -> 17454797991 | D7: =BS_ORIG!E9 -> 1.9910884e+10 | E7: =BS_ORIG!F9 -> 2.537087e+10 | F7: =BS_ORIG!G9 -> 2.4328693e+10 | G7: =BS_ORIG!H9 -> 2.2146279e+10 | H7: =SUM(H3:H6) -> 1.5459047e+10 | I7: =SUM(I3:I6) -> 1.5404305e+10 | J7: =SUM(J3:J6) -> 1.3151328e+10 | K7: =SUM(K3:K6) -> 1.1674281e+10 | L7: =SUM(L3:L6) -> 9.7836732e+09
A9: Property, Plant and Equipment | B9: =BS_ORIG!C10 -> 1.9680651e+09 | C9: =BS_ORIG!D10 -> 1.8367497e+09 | D9: =BS_ORIG!E10 -> 1.7293135e+09 | E9: =BS_ORIG!F10 -> 1.4216552e+09 | F9: =BS_ORIG!G10 -> 1.3043049e+09 | G9: =BS_ORIG!H10 -> 1.2368576e+09 | H9: =Assumption!G18*IS!H3 -> 1.1244375e+09 | I9: =Assumption!H18*IS!I3 -> 1.1057243e+09 | J9: =Assumption!I18*IS!J3 -> 9.1933566e+08 | K9: =Assumption!J18*IS!K3 -> 8.8135048e+08 | L9: =Assumption!K18*IS!L3 -> 8.2374905e+08
A10: Intangible assets | B10: =BS_ORIG!C11 -> 3.6853816e+08 | C10: =BS_ORIG!D11 -> 2.7100475e+08 | D10: =BS_ORIG!E11 -> 2.5111901e+08 | E10: =BS_ORIG!F11 -> 2.1482327e+08 | F10: =BS_ORIG!G11 -> 1.951898e+08 | G10: =BS_ORIG!H11 -> 1.8835227e+08 | H10: =IS!H3*Assumption!G19 -> 1.6738515e+08 | I10: =IS!I3*Assumption!H19 -> 1.6488993e+08 | J10: =IS!J3*Assumption!I19 -> 1.3806043e+08 | K10: =IS!K3*Assumption!J19 -> 1.3223152e+08 | L10: =IS!L3*Assumption!K19 -> 1.2365016e+08
A11: Total other non-current assets | B11: =B12-SUM(B9:B10) -> 2.7075851e+09 | C11: =C12-SUM(C9:C10) -> 3.024165e+09 | D11: =D12-SUM(D9:D10) -> 3.9734349e+09 | E11: =E12-SUM(E9:E10) -> 4.818765e+09 | F11: =F12-SUM(F9:F10) -> 4.5597074e+09 | G11: =G12-SUM(G9:G10) -> 4.9008661e+09 | H11: =IS!H3*Assumption!G20 -> 3.2631667e+09 | I11: =IS!I3*Assumption!H20 -> 3.4861063e+09 | J11: =IS!J3*Assumption!I20 -> 3.1095683e+09 | K11: =IS!K3*Assumption!J20 -> 2.9801352e+09 | L11: =IS!L3*Assumption!K20 -> 2.7671654e+09
A12: Total non-current assets | B12: =BS_ORIG!C12 -> 5.0441884e+09 | C12: =BS_ORIG!D12 -> 5.1319195e+09 | D12: =BS_ORIG!E12 -> 5.9538674e+09 | E12: =BS_ORIG!F12 -> 6.4552434e+09 | F12: =BS_ORIG!G12 -> 6.0592021e+09 | G12: =BS_ORIG!H12 -> 6.326076e+09 | H12: =SUM(H9:H11) -> 4.5549894e+09 | I12: =SUM(I9:I11) -> 4.7567206e+09 | J12: =SUM(J9:J11) -> 4.1669644e+09 | K12: =SUM(K9:K11) -> 3.9937172e+09 | L12: =SUM(L9:L11) -> 3.7145646e+09
A13: Total assets | B13: =B7+B12 -> 1.7004836e+10 | C13: =C7+C12 -> 2.2586717e+10 | D13: =D7+D12 -> 2.5864752e+10 | E13: =E7+E12 -> 3.1826113e+10 | F13: =F7+F12 -> 3.0387895e+10 | G13: =G7+G12 -> 2.8472355e+10 | H13: =H7+H12 -> 2.0014037e+10 | I13: =I7+I12 -> 2.0161025e+10 | ... L13: =L7+L12 -> 1.3498238e+10
A15: Short debt | B15: =BS_ORIG!C14 -> 2.3983231e+09 | C15: =BS_ORIG!D14 -> 3.0195183e+09 | D15: =BS_ORIG!E14 -> 6847020000 | E15: =BS_ORIG!F14 -> 6269244000 | F15: =BS_ORIG!G14 -> 5.3057837e+09 | G15: =BS_ORIG!H14 -> 4694800000 | H15: =IS!H3*Assumption!G21 -> 3.9931165e+09 | I15: =IS!I3*Assumption!H21 -> 4.3478119e+09 | J15: =IS!J3*Assumption!I21 -> 3.6081763e+09 | K15: =IS!K3*Assumption!J21 -> 3.3944094e+09 | L15: =IS!L3*Assumption!K21 -> 3.1381651e+09
A16: Notes and account payable | B16: =SUM(BS_ORIG!C15:C16) -> 5.0146689e+09 | C16: =SUM(BS_ORIG!D15:D16) -> 7.5322643e+09 | D16: =SUM(BS_ORIG!E15:E16) -> 7.7395232e+09 | E16: =SUM(BS_ORIG!F15:F16) -> 1.066042e+10 | F16: =SUM(BS_ORIG!G15:G16) -> 9.8259089e+09 | G16: =SUM(BS_ORIG!H15:H16) -> 9.6005362e+09 | H16: =Assumption!G22*IS!H3 -> 6.8732007e+09 | I16: =Assumption!H22*IS!I3 -> 7.2030258e+09 | J16: =Assumption!I22*IS!J3 -> 6.4921785e+09 | K16: =Assumption!J22*IS!K3 -> 6.1656875e+09 | L16: =Assumption!K22*IS!L3 -> 5.677297e+09
A17: Total other current liabilities | B17: =B18-SUM(B15:B16) -> 2.7461858e+09 | C17: =C18-SUM(C15:C16) -> 5.1611109e+09 | D17: =D18-SUM(D15:D16) -> 5.5203991e+09 | E17: =E18-SUM(E15:E16) -> 5.7052634e+09 | F17: =F18-SUM(F15:F16) -> 7.2133728e+09 | G17: =G18-SUM(G15:G16) -> 8.1779025e+09 | H17: =Assumption!G23*IS!H3 -> 4.934925e+09 | I17: =Assumption!H23*IS!I3 -> 5.2014343e+09 | J17: =Assumption!I23*IS!J3 -> 4.6978907e+09 | K17: =Assumption!J23*IS!K3 -> 4.6500696e+09 | L17: =Assumption!K23*IS!L3 -> 4.3057501e+09
A18: Total current liabilities | B18: =BS_ORIG!C17 -> 1.0159178e+10 | C18: =BS_ORIG!D17 -> 1.5712893e+10 | D18: =BS_ORIG!E17 -> 2.0106942e+10 | E18: =BS_ORIG!F17 -> 2.2634928e+10 | F18: =BS_ORIG!G17 -> 2.2345065e+10 | G18: =BS_ORIG!H17 -> 2.2473239e+10 | H18: =SUM(H15:H17) -> 1.5801242e+10 | I18: =SUM(I15:I17) -> 1.6752272e+10 | J18: =SUM(J15:J17) -> 1.4798246e+10 | K18: =SUM(K15:K17) -> 1.4210166e+10 | L18: =SUM(L15:L17) -> 1.3121212e+10
A20: Long-term debt | B20: =SUM(BS_ORIG!C18:C18) -> 2.0456948e+09 | C20: =SUM(BS_ORIG!D18:D18) -> 2.5194239e+09 | D20: =SUM(BS_ORIG!E18:E18) -> 6.6594997e+08 | E20: =SUM(BS_ORIG!F18:F18) -> 4.6298266e+09 | F20: =SUM(BS_ORIG!G18:G18) -> 4916500000 | G20: =SUM(BS_ORIG!H18:H18) -> 3730500000 | H20: =Assumption!G24*IS!H3 -> 2.4727953e+09 | I20: =Assumption!H24*IS!I3 -> 2.6143576e+09 | J20: =Assumption!I24*IS!J3 -> 2.6623124e+09 | K20: =Assumption!J24*IS!K3 -> 2.5042051e+09 | L20: =Assumption!K24*IS!L3 -> 2.1930924e+09
A21: Total other non-current liabilities | B21: =B22-B20 -> 2.0193366e+09 | C21: =C22-C20 -> 1.1945717e+09 | D21: =D22-D20 -> 7.3457399e+08 | E21: =E22-E20 -> 62362123 | F21: =F22-F20 -> 39852845 | G21: =G22-G20 -> 31356152 | H21: =Assumption!G25*IS!H3 -> 2.8723835e+08 | I21: =Assumption!H25*IS!I3 -> 1.9525394e+08 | J21: =Assumption!I25*IS!J3 -> 1.0106637e+08 | K21: =Assumption!J25*IS!K3 -> 1.0570097e+08 | L21: =Assumption!K25*IS!L3 -> 1.1299182e+08
A22: Total non-current liabilities | B22: =BS_ORIG!C19 -> 4.0650314e+09 | C22: =BS_ORIG!D19 -> 3.7139956e+09 | D22: =BS_ORIG!E19 -> 1.400524e+09 | E22: =BS_ORIG!F19 -> 4.6921888e+09 | F22: =BS_ORIG!G19 -> 4.9563528e+09 | G22: =BS_ORIG!H19 -> 3.7618562e+09 | H22: =SUM(H20:H21) -> 2.7600336e+09 | I22: =SUM(I20:I21) -> 2.8096116e+09 | J22: =SUM(J20:J21) -> 2.7633787e+09 | K22: =SUM(K20:K21) -> 2.6099061e+09 | L22: =SUM(L20:L21) -> 2.3060842e+09
A23: Total liabilities | B23: =BS_ORIG!C20 -> 1.4224209e+10 | C23: =BS_ORIG!D20 -> 1.9426889e+10 | D23: =BS_ORIG!E20 -> 2.1507466e+10 | E23: =BS_ORIG!F20 -> 2.7327117e+10 | F23: =BS_ORIG!G20 -> 2.7301418e+10 | G23: =BS_ORIG!H20 -> 2.6235095e+10 | H23: =H18+H22 -> 1.8561276e+10 | I23: =I18+I22 -> 1.9561884e+10 | J23: =J18+J22 -> 1.7561624e+10 | K23: =K18+K22 -> 1.6820073e+10 | L23: =L18+L22 -> 1.5427296e+10
A25: Retained earnings | B25: =SUM(BS_ORIG!C21:C21) -> 2.6353643e+08 | C25: =SUM(BS_ORIG!D21:D21) -> 4.7304471e+08 | D25: =SUM(BS_ORIG!E21:E21) -> 5.4764745e+08 | E25: =SUM(BS_ORIG!F21:F21) -> 5.2530989e+08 | F25: =SUM(BS_ORIG!G21:G21) -> -6.3420741e+08 | G25: =SUM(BS_ORIG!H21:H21) -> -1.3275272e+09 | H25: =Assumption!G29 -> -2.1120267e+09 | I25: =Assumption!H29 -> -2.9656461e+09 | J25: =Assumption!I29 -> -3.8081192e+09 | K25: =Assumption!J29 -> -4.7168627e+09 | L25: =Assumption!K29 -> -5.4938464e+09
A26: Minority interests | B26: =BS_ORIG!C22 -> 2.9510072e+08 | C26: =BS_ORIG!D22 -> 4.4773833e+08 | D26: =BS_ORIG!E22 -> 5.5987292e+08 | E26: =BS_ORIG!F22 -> 8.2977025e+08 | F26: =BS_ORIG!G22 -> 5.8336913e+08 | G26: =BS_ORIG!H22 -> 4.2696555e+08 | H26: =G26 -> 4.2696555e+08 | I26: =H26 -> 4.2696555e+08 | J26: =I26 -> 4.2696555e+08 | K26: =J26 -> 4.2696555e+08 | L26: =K26 -> 4.2696555e+08
A27: Others | B27: =B28-SUM(B25:B26) -> 2.2219892e+09 | C27: =C28-SUM(C25:C26) -> 2.2390453e+09 | D27: =D28-SUM(D25:D26) -> 3.2497653e+09 | E27: =E28-SUM(E25:E26) -> 3.1439163e+09 | F27: =F28-SUM(F25:F26) -> 3.1373154e+09 | G27: =G28-SUM(G25:G26) -> 3.1378222e+09 | H27: =G27 -> 3.1378222e+09 | I27: =H27 -> 3.1378222e+09 | J27: =I27 -> 3.1378222e+09 | K27: =J27 -> 3.1378222e+09 | L27: =K27 -> 3.1378222e+09
A28: Total shareholders' equity | B28: =BS_ORIG!C23 -> 2.7806264e+09 | C28: =BS_ORIG!D23 -> 3.1598283e+09 | D28: =BS_ORIG!E23 -> 4.3572856e+09 | E28: =BS_ORIG!F23 -> 4.4989964e+09 | F28: =BS_ORIG!G23 -> 3.0864771e+09 | G28: =BS_ORIG!H23 -> 2.2372606e+09 | H28: =SUM(H25:H27) -> 1.452761e+09 | I28: =SUM(I25:I27) -> 5.9914167e+08 | J28: =SUM(J25:J27) -> -2.4333148e+08 | K28: =SUM(K25:K27) -> -1.1520749e+09 | L28: =SUM(L25:L27) -> -1.9290587e+09
A29: Total liabilities and Shareholders' equity | B29: =BS!B28+BS!B23 -> 1.7004836e+10 | C29: =BS!C28+BS!C23 -> 2.2586717e+10 | D29: =BS!D28+BS!D23 -> 2.5864752e+10 | E29: =BS!E28+BS!E23 -> 3.1826113e+10 | F29: =BS!F28+BS!F23 -> 3.0387895e+10 | G29: =BS!G28+BS!G23 -> 2.8472355e+10 | H29: =H23+H28 -> 2.0014037e+10 | I29: =I23+I28 -> 2.0161025e+10 | J29: =J23+J28 -> 1.7318293e+10 | K29: =K23+K28 -> 1.5667998e+10 | L29: =L23+L28 -> 1.3498238e+10
A30: check | B30: =B13-B29 -> 0 | C30: =C13-C29 -> 0 | D30: =D13-D29 -> 0 | E30: =E13-E29 -> 0 | F30: =F13-F29 -> 0 | G30: =G13-G29 -> 0 | H30: =H13-H29 -> 0 | I30: =I13-I29 -> 0 | ... L30: =L13-L29 -> 0
A34: +Cash and equivalent | B34: =TLE-TNCA-A
A35: +A(All other items in current assets)
A36: =Total current assets
A37: +Total non-current assets | B37: TNCA
A38: =Total assets (TA) | B38: TA=Cash+A+TNCA=TLE
A40: =Total liabilities and shareholders equity | B40: TLE

Sheet IS
B1: N-5 | C1: N-4 | D1: N-3 | E1: N-2 | F1: N-1 | G1: N | H1: N+1E | I1: N+2E | J1: N+3E | K1: N+4E | L1: N+5E
B2: 2016 | C2: 2017 | D2: 2018 | E2: 2019 | F2: 2020 | G2: 2021 | H2: 2022 | I2: 2023 | J2: 2024 | K2: 2025 | L2: 2026
A3: Total Revenue | B3: =IS_ORIG!C3 -> 1.1951452e+09 | C3: =IS_ORIG!D3 -> 1.0403684e+10 | D3: =IS_ORIG!E3 -> 7.7001635e+09 | E3: =IS_ORIG!F3 -> 1.0779197e+10 | F3: =IS_ORIG!G3 -> 7.7124736e+09 | G3: =IS_ORIG!H3 -> 6.8067912e+09 | H3: ='Sales forecast'!H3 -> 6.3610645e+09 | I3: ='Sales forecast'!I3 -> 6.2536398e+09 | J3: ='Sales forecast'!J3 -> 5.4964722e+09 | K3: ='Sales forecast'!K3 -> 5.0555484e+09 | L3: ='Sales forecast'!L3 -> 4.6970264e+09
A4: Cost of goods sold | B4: =IS_ORIG!C4 -> 9.7983838e+08 | C4: =IS_ORIG!D4 -> 9.2813995e+09 | D4: =IS_ORIG!E4 -> 6.5582098e+09 | E4: =IS_ORIG!F4 -> 9.2800606e+09 | F4: =IS_ORIG!G4 -> 7.6896156e+09 | G4: =IS_ORIG!H4 -> 5.6706337e+09 | H4: =Assumption!G3*IS!$H$3 -> 5.6420961e+09 | I4: =Assumption!H3*IS!$I$3 -> 5.5403687e+09 | J4: =Assumption!I3*IS!$J$3 -> 4.9072072e+09 | K4: =Assumption!J3*IS!$K$3 -> 4.545777e+09 | L4: =Assumption!K3*IS!$L$3 -> 4.1314663e+09
A5: Main operating expenses | B5: =IS_ORIG!C5+IS_ORIG!C6+IS_ORIG!C7+IS_ORIG!C8 -> 2.9278802e+08 | C5: =IS_ORIG!D5+IS_ORIG!D6+IS_ORIG!D7+IS_ORIG!D8 -> 4.473324e+08 | D5: =IS_ORIG!E5+IS_ORIG!E6+IS_ORIG!E7+IS_ORIG!E8 -> 4.4105032e+08 | E5: =IS_ORIG!F5+IS_ORIG!F6+IS_ORIG!F7+IS_ORIG!F8 -> 4.561049e+08 | F5: =IS_ORIG!G5+IS_ORIG!G6+IS_ORIG!G7+IS_ORIG!G8 -> 5.8825654e+08 | G5: =IS_ORIG!H5+IS_ORIG!H6+IS_ORIG!H7+IS_ORIG!H8 -> 5.1608687e+08 | H5: =Assumption!G4*IS!$H$3 -> 3.7489797e+08 | I5: =Assumption!H4*IS!$I$3 -> 3.8850193e+08 | J5: =Assumption!I4*IS!$J$3 -> 3.4679082e+08 | K5: =Assumption!J4*IS!$K$3 -> 3.3998223e+08 | L5: =Assumption!K4*IS!$L$3 -> 3.073946e+08
A6: Investment income | B6: =IS_ORIG!C9 -> -1948003.4 | C6: =IS_ORIG!D9 -> 1.3407863e+08 | D6: =IS_ORIG!E9 -> 88534509 | E6: =IS_ORIG!F9 -> -1.3235346e+08 | F6: =IS_ORIG!G9 -> 78508508 | G6: =IS_ORIG!H9 -> 79056432 | H6: =Assumption!G5*IS!$H$3 -> 43128681 | I6: =Assumption!H5*IS!$I$3 -> 34761501 | J6: =Assumption!I5*IS!$J$3 -> 24023842 | K6: =Assumption!J5*IS!$K$3 -> 38931008 | L6: =Assumption!K5*IS!$L$3 -> 33841585
A7: Impairment losses | B7: =IS_ORIG!C10+IS_ORIG!C11 -> 97519459 | C7: =IS_ORIG!D10+IS_ORIG!D11 -> 1.0144876e+08 | D7: =IS_ORIG!E10+IS_ORIG!E11 -> 2.5506934e+08 | E7: =-(IS_ORIG!F10+IS_ORIG!F11) -> 2.1185981e+08 | F7: =-(IS_ORIG!G10+IS_ORIG!G11) -> 7.0995769e+08 | G7: =-(IS_ORIG!H10+IS_ORIG!H11) -> 1.0853345e+09 | H7: =H3*Assumption!G6 -> 3.9951669e+08 | I7: =I3*Assumption!H6 -> 4.5912751e+08 | J7: =J3*Assumption!I6 -> 4.4783132e+08 | K7: =K3*Assumption!J6 -> 4.7441501e+08 | L7: =L3*Assumption!K6 -> 4.4245012e+08
A8: Gains/(Loss) from fair value changes | B8: =IS_ORIG!C12 -> 0 | C8: =IS_ORIG!D12 -> 0 | D8: =IS_ORIG!E12 -> 0 | E8: =IS_ORIG!F12 -> 0 | F8: =IS_ORIG!G12 -> 0 | G8: =IS_ORIG!H12 -> 0 | H8: =H3*Assumption!G7 -> 0 | I8: =I3*Assumption!H7 -> 0 | J8: =J3*Assumption!I7 -> 0 | K8: =K3*Assumption!J7 -> 0 | L8: =L3*Assumption!K7 -> 0
A9: Gains/(Loss) on disposal of assets | B9: =IS_ORIG!C13 -> 0 | C9: =IS_ORIG!D13 -> 3946601 | D9: =IS_ORIG!E13 -> -1576500.1 | E9: =IS_ORIG!F13 -> 1439776 | F9: =IS_ORIG!G13 -> 19545451 | G9: =IS_ORIG!H13 -> 1815179.8 | H9: =H3*Assumption!G8 -> 3955459 | I9: =I3*Assumption!H8 -> 4191932.5 | J9: =J3*Assumption!I8 -> 4646331.6 | K9: =K3*Assumption!J8 -> 4993273 | L9: =L3*Assumption!K8 -> 3186298.9
A10: + Interest expense | B10: =IS_ORIG!C15 -> 0 | C10: =IS_ORIG!D15 -> 0 | D10: =IS_ORIG!E15 -> 3.0102171e+08 | E10: =IS_ORIG!F15 -> 4.8974373e+08 | F10: =IS_ORIG!G15 -> 5.1232358e+08 | G10: =IS_ORIG!H15 -> 4.8683431e+08 | H10: =Assumption!G31*(BS!H15+BS!H20) -> 1.7630757e+08 | I10: =Assumption!H31*(BS!I15+BS!I20) -> 2.2780699e+08 | J10: =Assumption!I31*(BS!J15+BS!J20) -> 2.4620966e+08 | K10: =Assumption!J31*(BS!K15+BS!K20) -> 2.453469e+08 | L10: =Assumption!K31*(BS!L15+BS!L20) -> 2.1501441e+08
A11: - Interest income | B11: =IS_ORIG!C16 -> 0 | C11: =IS_ORIG!D16 -> 0 | D11: =IS_ORIG!E16 -> 2782474.2 | E11: =IS_ORIG!F16 -> 29324587 | F11: =IS_ORIG!G16 -> 22173471 | G11: =IS_ORIG!H16 -> 10913197 | H11: =Assumption!G32*BS!H3 -> 2253484.1 | I11: =Assumption!H32*BS!I3 -> -3226261.3 | J11: =Assumption!I32*BS!J3 -> -8809262.7 | K11: =Assumption!J32*BS!K3 -> -14456427 | L11: =Assumption!K32*BS!L3 -> -19270286
A12: + Others (Net financial expense) | B12: =B13-B10+B11 -> 1.8309135e+08 | C12: =C13-C10+C11 -> 4.4675826e+08 | D12: =D13-D10+D11 -> 34281755 | E12: =E13-E10+E11 -> 40973399 | F12: =F13-F10+F11 -> 22000620 | G12: =G13-G10+G11 -> 8163558.7 | H12: =AVERAGE(B12:G12) -> 1.2254482e+08 | I12: =AVERAGE(C12:H12) -> 1.1245374e+08 | J12: =AVERAGE(D12:I12) -> 56736315 | K12: =AVERAGE(E12:J12) -> 60478742 | L12: =AVERAGE(F12:K12) -> 63729633
A13: = Net Financial expense/(income) | B13: =IS_ORIG!C14 -> 1.8309135e+08 | C13: =IS_ORIG!D14 -> 4.4675826e+08 | D13: =IS_ORIG!E14 -> 3.3252099e+08 | E13: =IS_ORIG!F14 -> 5.0139254e+08 | F13: =IS_ORIG!G14 -> 5.1215073e+08 | G13: =IS_ORIG!H14 -> 4.8408467e+08 | H13: =H10-H11+H12 -> 2.9659891e+08 | I13: =I10-I11+I12 -> 3.4348699e+08 | J13: =J10-J11+J12 -> 3.1175523e+08 | K13: =K10-K11+K12 -> 3.2028207e+08 | L13: =L10-L11+L12 -> 2.9801433e+08
A14: All others | B14: =B15-(B3-B4-B5+B6-B7+B8+B9+B13) -> -3.661827e+08 | C14: =C15-(C3-C4-C5+C6-C7+C8+C9+C13) -> -8.823733e+08 | D14: =D15-(D3-D4-D5+D6-D7+D8+D9+D13) -> -6.5490321e+08 | E14: =E15-(E3-E4-E5+E6-E7+E8+E9+E13) -> -9.8849514e+08 | F14: =F15-(F3-F4-F5+F6-F7+F8+F9+F13) -> -1.0052577e+09 | G14: =G15-(G3-G4-G5+G6-G7+G8+G9+G13) -> -9.5519477e+08 | H14: =H3*Assumption!G9 -> -6.7712202e+08 | I14: =I3*Assumption!H9 -> -6.9274559e+08 | J14: =J3*Assumption!I9 -> -6.3714901e+08 | K14: =K3*Assumption!J9 -> -6.1052197e+08 | L14: =L3*Assumption!K9 -> -5.5822726e+08
A15: Operating profit | B15: =IS_ORIG!C17 -> -3.6003997e+08 | C15: =IS_ORIG!D17 -> 2.7591308e+08 | D15: =IS_ORIG!E17 -> 2.1040982e+08 | E15: =IS_ORIG!F17 -> 2.131555e+08 | F15: =IS_ORIG!G17 -> -1.6704093e+09 | G15: =IS_ORIG!H17 -> -8.5550241e+08 | H15: =H3-H4-H5+H6-H7+H8+H9-H13+H14 -> -9.8208308e+08 | I15: =I3-I4-I5+I6-I7+I8+I9-I13+I14 -> -1.1316374e+09 | J15: =J3-J4-J5+J6-J7+J8+J9-J13+J14 -> -1.1255912e+09 | K15: =K3-K4-K5+K6-K7+K8+K9-K13+K14 -> -1.1915055e+09 | L15: =L3-L4-L5+L6-L7+L8+L9-L13+L14 -> -1.0034983e+09
A16: Non-operating income/(expense) | B16: =IS_ORIG!C18-IS_ORIG!C19 -> 16683179 | C16: =IS_ORIG!D18-IS_ORIG!D19 -> -8711726.7 | D16: =IS_ORIG!E18-IS_ORIG!E19 -> -8907585.1 | E16: =IS_ORIG!F18-IS_ORIG!F19 -> -36790736 | F16: =IS_ORIG!G18-IS_ORIG!G19 -> -4430763.2 | G16: =IS_ORIG!H18-IS_ORIG!H19 -> -2480148.5 | H16: =Assumption!G10*IS!$H$3 -> -8073660.4 | I16: =Assumption!H10*IS!$I$3 -> -8477455 | J16: =Assumption!I10*IS!$J$3 -> -7669574.3 | K16: =Assumption!J10*IS!$K$3 -> -5014147.9 | L16: =Assumption!K10*IS!$L$3 -> -5050592.3
A17: Total profit | B17: =IS_ORIG!C20 -> -3.433568e+08 | C17: =IS_ORIG!D20 -> 2.6720136e+08 | D17: =IS_ORIG!E20 -> 2.0150224e+08 | E17: =IS_ORIG!F20 -> 1.7636476e+08 | F17: =IS_ORIG!G20 -> -1.6748401e+09 | G17: =IS_ORIG!H20 -> -8.5798256e+08 | H17: =H15+H16 -> -9.9015674e+08 | I17: =I15+I16 -> -1.1401149e+09 | J17: =J15+J16 -> -1.1332608e+09 | K17: =K15+K16 -> -1.1965197e+09 | L17: =L15+L16 -> -1.0085489e+09
A18: Income Tax Expenses | B18: =IS_ORIG!C21 -> -37460937 | C18: =IS_ORIG!D21 -> -53315272 | D18: =IS_ORIG!E21 -> 16014110 | E18: =IS_ORIG!F21 -> 37524520 | F18: =IS_ORIG!G21 -> -2.7291958e+08 | G18: =IS_ORIG!H21 -> -34739082 | H18: =H17*Assumption!G11 -> -58646952 | I18: =I17*Assumption!H11 -> -1.2653268e+08 | J18: =J17*Assumption!I11 -> -1.3291354e+08 | K18: =K17*Assumption!J11 -> -1.1748349e+08 | L18: =L17*Assumption!K11 -> -85963359
A19: Net profit | B19: =IS_ORIG!C22 -> -3.0589586e+08 | C19: =IS_ORIG!D22 -> 3.2051663e+08 | D19: =IS_ORIG!E22 -> 1.8548813e+08 | E19: =IS_ORIG!F22 -> 1.3884024e+08 | F19: =IS_ORIG!G22 -> -1.4019205e+09 | G19: =IS_ORIG!H22 -> -8.2324348e+08 | H19: =H17-H18 -> -9.3150979e+08 | I19: =I17-I18 -> -1.0135822e+09 | J19: =J17-J18 -> -1.0003473e+09 | K19: =K17-K18 -> -1.0790362e+09 | L19: =L17-L18 -> -9.2258556e+08
A20: Net Profit Attributable To Owners Of The Parent Company | B20: =IS_ORIG!C23 -> -2.9971088e+08 | C20: =IS_ORIG!D23 -> 2.2514558e+08 | D20: =IS_ORIG!E23 -> 74602747 | E20: =IS_ORIG!F23 -> 42391861 | F20: =IS_ORIG!G23 -> -1.1595173e+09 | G20: =IS_ORIG!H23 -> -6.9331976e+08 | H20: =H19*H21 -> -7.8449956e+08 | I20: =I19*I21 -> -8.5361934e+08 | J20: =J19*J21 -> -8.4247315e+08 | K20: =K19*K21 -> -9.0874344e+08 | L20: =L19*L21 -> -7.7698374e+08
A21: Net Profit Attributable To Owners Of The Parent Company/Net profit | B21: =B20/B19 -> 0.97978077 | C21: =C20/C19 -> 0.70244586 | D21: =D20/D19 -> 0.40219689 | E21: =E20/E19 -> 0.30532834 | F21: =F20/F19 -> 0.82709206 | G21: =G20/G19 -> 0.84218069 | H21: =G21 -> 0.84218069 | I21: =H21 -> 0.84218069 | J21: =I21 -> 0.84218069 | K21: =J21 -> 0.84218069 | L21: =K21 -> 0.84218069
A24: Dividends to shareholders of the company | B24: 0 | C24: 0 | D24: 0 | E24: 1.2611658e+08 | F24: 0 | G24: 0 | H24: =H25*H20 -> 0 | I24: =I25*I20 -> 0 | J24: =J25*J20 -> 0 | K24: =K25*K20 -> 0 | L24: =L25*L20 -> 0
A25: Dividends payout ratio | C25: =C24/C20 -> 0 | D25: =D24/D20 -> 0 | E25: =E24/E20 -> 2.9750187 | F25: =F24/F20 -> 0 | G25: =G24/G20 -> 0 | H25: 0 | I25: 0 | J25: 0 | K25: 0 | L25: 0

Sheet Sales forecast
B1: N-5 | C1: N-4 | D1: N-3 | E1: N-2 | F1: N-1 | G1: N | H1: N+1E | I1: N+2E | J1: N+3E | K1: N+4E | L1: N+5E
B2: 2016 | C2: 2017 | D2: 2018 | E2: 2019 | F2: 2020 | G2: 2021 | H2: 2022 | I2: 2023 | J2: 2024 | K2: 2025 | L2: 2026
A3: Total Revenue | B3: =IS_ORIG!C3 -> 1.1951452e+09 | C3: =IS_ORIG!D3 -> 1.0403684e+10 | D3: =IS_ORIG!E3 -> 7.7001635e+09 | E3: =IS_ORIG!F3 -> 1.0779197e+10 | F3: =IS_ORIG!G3 -> 7.7124736e+09 | G3: =IS_ORIG!H3 -> 6.8067912e+09 | H3: =G3*(1+H4) -> 6.3610645e+09 | I3: =H3*(1+I4) -> 6.2536398e+09 | J3: =I3*(1+J4) -> 5.4964722e+09 | K3: =J3*(1+K4) -> 5.0555484e+09 | L3: =K3*(1+L4) -> 4.6970264e+09
A4: YOY | C4: =C3/B3-1 -> 7.7049533 | D4: =D3/C3-1 -> -0.25986181 | E4: =E3/D3-1 -> 0.399866 | F4: =F3/E3-1 -> -0.28450389 | G4: =G3/F3-1 -> -0.11743086 | H4: =AVERAGE(D4:G4) -> -0.06548264 | I4: =AVERAGE(E4:H4) -> -0.016887846 | J4: =AVERAGE(F4:I4) -> -0.12107631 | K4: =AVERAGE(G4:J4) -> -0.080219413 | L4: =AVERAGE(H4:K4) -> -0.070916552

Sheet Assumption
A1: Financial ratio assumption for forecast | B1: N-4 | C1: N-3 | D1: N-2 | E1: N-1 | F1: N | G1: N+1E | H1: N+2E | I1: N+3E | J1: N+4E | K1: N+5E
B2: 2017 | C2: 2018 | D2: 2019 | E2: 2020 | F2: 2021 | G2: 2022 | H2: 2023 | I2: 2024 | J2: 2025 | K2: 2026
A3: Cost of goods sold/Sales | B3: =IS!C4/IS!C3 -> 0.89212628 | C3: =IS!D4/IS!D3 -> 0.85169747 | D3: =IS!E4/IS!E3 -> 0.86092318 | E3: =IS!F4/IS!F3 -> 0.99703624 | F3: =IS!G4/IS!G3 -> 0.83308471 | G3: =AVERAGE(B3:F3) -> 0.88697358 | H3: =AVERAGE(C3:G3) -> 0.88594304 | I3: =AVERAGE(D3:H3) -> 0.89279215 | J3: =AVERAGE(E3:I3) -> 0.89916594 | K3: =AVERAGE(F3:J3) -> 0.87959188
A4: Main operating expenses/Sales | B4: =IS!C5/IS!C3 -> 0.042997502 | C4: =IS!D5/IS!D3 -> 0.057278046 | D4: =IS!E5/IS!E3 -> 0.042313439 | E4: =IS!F5/IS!F3 -> 0.076273395 | F4: =IS!G5/IS!G3 -> 0.075819407 | G4: =AVERAGE(B4:F4) -> 0.058936358 | H4: =AVERAGE(C4:G4) -> 0.062124129 | I4: =AVERAGE(D4:H4) -> 0.063093346 | J4: =AVERAGE(E4:I4) -> 0.067249327 | K4: =AVERAGE(F4:J4) -> 0.065444513
A5: Investment income/Sales | B5: =IS!C6/IS!C3 -> 0.012887611 | C5: =IS!D6/IS!D3 -> 0.011497744 | D5: =IS!E6/IS!E3 -> -0.012278601 | E5: =IS!F6/IS!F3 -> 0.01017942 | F5: =IS!G6/IS!G3 -> 0.011614347 | G5: =AVERAGE(B5:F5) -> 0.0067801043 | H5: =AVERAGE(C5:G5) -> 0.0055586029 | I5: =AVERAGE(D5:H5) -> 0.0043707747 | J5: =AVERAGE(E5:I5) -> 0.0077006497 | K5: =AVERAGE(F5:J5) -> 0.0072048957
A6: Impairment losses/Sales | B6: =IS!C7/IS!C3 -> 0.0097512345 | C6: =IS!D7/IS!D3 -> 0.033125186 | D6: =IS!E7/IS!E3 -> 0.019654508 | E6: =IS!F7/IS!F3 -> 0.092053177 | F6: =IS!G7/IS!G3 -> 0.15944878 | G6: =AVERAGE(B6:F6) -> 0.062806577 | H6: =AVERAGE(C6:G6) -> 0.073417645 | I6: =AVERAGE(D6:H6) -> 0.081476137 | J6: =AVERAGE(E6:I6) -> 0.093840463 | K6: =AVERAGE(F6:J6) -> 0.09419792
A7: Net Income from Fair Value Changes/Sales | B7: =IS!C8/IS!C3 -> 0 | C7: =IS!D8/IS!D3 -> 0 | D7: =IS!E8/IS!E3 -> 0 | E7: =IS!F8/IS!F3 -> 0 | F7: =IS!G8/IS!G3 -> 0 | G7: =AVERAGE(B7:F7) -> 0 | H7: =AVERAGE(C7:G7) -> 0 | I7: =AVERAGE(D7:H7) -> 0 | J7: =AVERAGE(E7:I7) -> 0 | K7: =AVERAGE(F7:J7) -> 0
A8: Gains/(Loss) on disposal of assets/Sales | B8: =IS!C9/IS!C3 -> 0.00037934651 | C8: =IS!D9/IS!D3 -> -0.00020473592 | D8: =IS!E9/IS!E3 -> 0.00013356987 | E8: =IS!F9/IS!F3 -> 0.0025342649 | F8: =IS!G9/IS!G3 -> 0.00026667189 | G8: =AVERAGE(B8:F8) -> 0.00062182344 | H8: =AVERAGE(C8:G8) -> 0.00067031883 | I8: =AVERAGE(D8:H8) -> 0.00084532978 | J8: =AVERAGE(E8:I8) -> 0.00098768176 | K8: =AVERAGE(F8:J8) -> 0.00067836514
A9: All others/Sales | B9: =IS!C14/IS!C3 -> -0.084813547 | C9: =IS!D14/IS!D3 -> -0.08505056 | D9: =IS!E14/IS!E3 -> -0.091703967 | E9: =IS!F14/IS!F3 -> -0.1303418 | F9: =IS!G14/IS!G3 -> -0.14032967 | G9: =AVERAGE(B9:F9) -> -0.10644791 | H9: =AVERAGE(C9:G9) -> -0.11077478 | I9: =AVERAGE(D9:H9) -> -0.11591963 | J9: =AVERAGE(E9:I9) -> -0.12076276 | K9: =AVERAGE(F9:J9) -> -0.11884695
A10: Non-operating income/(expense)/Sales | B10: =IS!C16/IS!C3 -> -0.00083736944 | C10: =IS!D16/IS!D3 -> -0.0011568047 | D10: =IS!E16/IS!E3 -> -0.003413124 | E10: =IS!F16/IS!F3 -> -0.00057449315 | F10: =IS!G16/IS!G3 -> -0.00036436383 | G10: =AVERAGE(B10:F10) -> -0.001269231 | H10: =AVERAGE(C10:G10) -> -0.0013556033 | I10: =AVERAGE(D10:H10) -> -0.0013953631 | J10: =AVERAGE(E10:I10) -> -0.00099181088 | K10: =AVERAGE(F10:J10) -> -0.0010752744
A11: Income taxe expenses/Total profits | B11: =IS!C18/IS!C17 -> -0.19953219 | C11: =IS!D18/IS!D17 -> 0.079473611 | D11: =IS!E18/IS!E17 -> 0.21276654 | E11: =IS!F18/IS!F17 -> 0.16295262 | F11: =IS!G18/IS!G17 -> 0.040489263 | G11: =AVERAGE(B11:F11) -> 0.059229968 | H11: =AVERAGE(C11:G11) -> 0.1109824 | I11: =AVERAGE(D11:H11) -> 0.11728416 | J11: =AVERAGE(E11:I11) -> 0.098187682 | K11: =AVERAGE(F11:J11) -> 0.085234694
A14: Cash and equivalent
A15: Notes and accounts receivable/Sales | B15: =BS!C4/IS!C3 -> 0.64209781 | C15: =BS!D4/IS!D3 -> 1.0098591 | D15: =BS!E4/IS!E3 -> 0.63626612 | E15: =BS!F4/IS!F3 -> 0.82489931 | F15: =BS!G4/IS!G3 -> 0.71935205 | G15: =AVERAGE(B15:F15) -> 0.76649488 | H15: =AVERAGE(C15:G15) -> 0.7913743 | I15: =AVERAGE(D15:H15) -> 0.74767733 | J15: =AVERAGE(E15:I15) -> 0.76995958 | K15: =AVERAGE(F15:J15) -> 0.75897163
A16: Inventory/Sales | B16: =BS!C5/IS!C3 -> 0.71505456 | C16: =BS!D5/IS!D3 -> 0.92382224 | D16: =BS!E5/IS!E3 -> 0.26984066 | E16: =BS!F5/IS!F3 -> 0.24817551 | F16: =BS!G5/IS!G3 -> 0.27417532 | G16: =AVERAGE(B16:F16) -> 0.48621366 | H16: =AVERAGE(C16:G16) -> 0.44044548 | I16: =AVERAGE(D16:H16) -> 0.34377013 | J16: =AVERAGE(E16:I16) -> 0.35855602 | K16: =AVERAGE(F16:J16) -> 0.38063212
A17: Total Other current assets/Sales | B17: =BS!C6/IS!C3 -> 0.19319004 | C17: =BS!D6/IS!D3 -> 0.35599588 | D17: =BS!E6/IS!E3 -> 1.2095317 | E17: =BS!F6/IS!F3 -> 1.787789 | F17: =BS!G6/IS!G3 -> 2.0450324 | G17: =AVERAGE(B17:F17) -> 1.1183078 | H17: =AVERAGE(C17:G17) -> 1.3033314 | I17: =AVERAGE(D17:H17) -> 1.4927985 | J17: =AVERAGE(E17:I17) -> 1.5494518 | K17: =AVERAGE(F17:J17) -> 1.5017844
A18: Property, Plant and Equipment/Sales | B18: =BS!C9/IS!C3 -> 0.17654802 | C18: =BS!D9/IS!D3 -> 0.2245814 | D18: =BS!E9/IS!E3 -> 0.13188878 | E18: =BS!F9/IS!F3 -> 0.16911628 | F18: =BS!G9/IS!G3 -> 0.18170935 | G18: =AVERAGE(B18:F18) -> 0.17676877 | H18: =AVERAGE(C18:G18) -> 0.17681292 | I18: =AVERAGE(D18:H18) -> 0.16725922 | J18: =AVERAGE(E18:I18) -> 0.17433331 | K18: =AVERAGE(F18:J18) -> 0.17537671
A19: Intangible assets/Sales | B19: =BS!C10/IS!C3 -> 0.026048923 | C19: =BS!D10/IS!D3 -> 0.032612166 | D19: =BS!E10/IS!E3 -> 0.019929432 | E19: =BS!F10/IS!F3 -> 0.025308326 | F19: =BS!G10/IS!G3 -> 0.027671228 | G19: =AVERAGE(B19:F19) -> 0.026314015 | H19: =AVERAGE(C19:G19) -> 0.026367033 | I19: =AVERAGE(D19:H19) -> 0.025118007 | J19: =AVERAGE(E19:I19) -> 0.026155722 | K19: =AVERAGE(F19:J19) -> 0.026325201
A20: Total other non-current assets/Sales | B20: =BS!C11/IS!C3 -> 0.29068214 | C20: =BS!D11/IS!D3 -> 0.51601955 | D20: =BS!E11/IS!E3 -> 0.44704304 | E20: =BS!F11/IS!F3 -> 0.59121206 | F20: =BS!G11/IS!G3 -> 0.71999654 | G20: =AVERAGE(B20:F20) -> 0.51299066 | H20: =AVERAGE(C20:G20) -> 0.55745237 | I20: =AVERAGE(D20:H20) -> 0.56573893 | J20: =AVERAGE(E20:I20) -> 0.58947811 | K20: =AVERAGE(F20:J20) -> 0.58913132
A21: Short debt/Sales | B21: =BS!C15/IS!C3 -> 0.2902355 | C21: =BS!D15/IS!D3 -> 0.8892045 | D21: =BS!E15/IS!E3 -> 0.58160584 | E21: =BS!F15/IS!F3 -> 0.68794838 | F21: =BS!G15/IS!G3 -> 0.68972294 | G21: =AVERAGE(B21:F21) -> 0.62774343 | H21: =AVERAGE(C21:G21) -> 0.69524502 | I21: =AVERAGE(D21:H21) -> 0.65645312 | J21: =AVERAGE(E21:I21) -> 0.67142258 | K21: =AVERAGE(F21:J21) -> 0.66811742
A22: Notes and account payable/Sales | B22: =BS!C16/IS!C3 -> 0.72399975 | C22: =BS!D16/IS!D3 -> 1.0051115 | D22: =BS!E16/IS!E3 -> 0.98898094 | E22: =BS!F16/IS!F3 -> 1.2740282 | F22: =BS!G16/IS!G3 -> 1.4104349 | G22: =AVERAGE(B22:F22) -> 1.0805111 | H22: =AVERAGE(C22:G22) -> 1.1518133 | I22: =AVERAGE(D22:H22) -> 1.1811537 | J22: =AVERAGE(E22:I22) -> 1.2195883 | K22: =AVERAGE(F22:J22) -> 1.2087003
A23: Total Other current liabilities/Sales | B23: =BS!C17/IS!C3 -> 0.49608495 | C23: =BS!D17/IS!D3 -> 0.71691972 | D23: =BS!E17/IS!E3 -> 0.52928464 | E23: =BS!F17/IS!F3 -> 0.93528655 | F23: =BS!G17/IS!G3 -> 1.2014329 | G23: =AVERAGE(B23:F23) -> 0.77580174 | H23: =AVERAGE(C23:G23) -> 0.8317451 | I23: =AVERAGE(D23:H23) -> 0.85471018 | J23: =AVERAGE(E23:I23) -> 0.91979529 | K23: =AVERAGE(F23:J23) -> 0.91669703
A24: Long-term debt/Sales | B24: =BS!C20/IS!C3 -> 0.24216653 | C24: =BS!D20/IS!D3 -> 0.086485173 | D24: =BS!E20/IS!E3 -> 0.42951498 | E24: =BS!F20/IS!F3 -> 0.63747382 | F24: =BS!G20/IS!G3 -> 0.5480556 | G24: =AVERAGE(B24:F24) -> 0.38873922 | H24: =AVERAGE(C24:G24) -> 0.41805376 | I24: =AVERAGE(D24:H24) -> 0.48436748 | J24: =AVERAGE(E24:I24) -> 0.49533798 | K24: =AVERAGE(F24:J24) -> 0.46691081
A25: Total Other non-current liabilities/Sales | B25: =BS!C21/IS!C3 -> 0.11482199 | C25: =BS!D21/IS!D3 -> 0.095397194 | D25: =BS!E21/IS!E3 -> 0.0057854145 | E25: =BS!F21/IS!F3 -> 0.0051673233 | F25: =BS!G21/IS!G3 -> 0.0046065983 | G25: =AVERAGE(B25:F25) -> 0.045155704 | H25: =AVERAGE(C25:G25) -> 0.031222447 | I25: =AVERAGE(D25:H25) -> 0.018387497 | J25: =AVERAGE(E25:I25) -> 0.020907914 | K25: =AVERAGE(F25:J25) -> 0.024056032
A26: Retained earnings-beginning balance | G26: =F29 -> -1.3275272e+09 | H26: =G29 -> -2.1120267e+09 | I26: =H29 -> -2.9656461e+09 | J26: =I29 -> -3.8081192e+09 | K26: =J29 -> -4.7168627e+09
A27: Net profit attributable to shareholders of the company | G27: =IS!H20 -> -7.8449956e+08 | H27: =IS!I20 -> -8.5361934e+08 | I27: =IS!J20 -> -8.4247315e+08 | J27: =IS!K20 -> -9.0874344e+08 | K27: =IS!L20 -> -7.7698374e+08
A28: Dividends to shareholders of the company | G28: =IS!H24 -> 0 | H28: =IS!I24 -> 0 | I28: =IS!J24 -> 0 | J28: =IS!K24 -> 0 | K28: =IS!L24 -> 0
A29: Retained earnings-end balance | F29: =BS!G25 -> -1.3275272e+09 | G29: =G26+G27-G28 -> -2.1120267e+09 | H29: =H26+H27-H28 -> -2.9656461e+09 | I29: =I26+I27-I28 -> -3.8081192e+09 | J29: =J26+J27-J28 -> -4.7168627e+09 | K29: =K26+K27-K28 -> -5.4938464e+09
A31: Interest expense/(Short-debt+long-term debt) | B31: =IF(BS!C15+BS!C20>0,IS!B10/(BS!C15+BS!C20),0) -> 0 | C31: =IF(BS!D15+BS!D20>0,IS!C10/(BS!D15+BS!D20),0) -> 0 | D31: =IF(BS!E15+BS!E20>0,IS!D10/(BS!E15+BS!E20),0) -> 0.027619026 | E31: =IF(BS!F15+BS!F20>0,IS!E10/(BS!F15+BS!F20),0) -> 0.047909425 | F31: =IF(BS!G15+BS!G20>0,IS!F10/(BS!G15+BS!G20),0) -> 0.060807755 | G31: =AVERAGE(B31:F31) -> 0.027267241 | H31: =AVERAGE(C31:G31) -> 0.032720689 | I31: =AVERAGE(D31:H31) -> 0.039264827 | J31: =AVERAGE(E31:I31) -> 0.041593988 | K31: =AVERAGE(F31:J31) -> 0.0403309
A32: Interest revenue/Cash and equivalent | B32: =IS!C11/BS!C3 -> 0 | C32: =IS!D11/BS!D3 -> 0.0012203859 | D32: =IS!E11/BS!E3 -> 0.011428194 | E32: =IS!F11/BS!F3 -> 0.0097923943 | F32: =IS!G11/BS!G3 -> 0.0074572349 | G32: =AVERAGE(B32:F32) -> 0.0059796419 | H32: =AVERAGE(C32:G32) -> 0.0071755703 | I32: =AVERAGE(D32:H32) -> 0.0083666072 | J32: =AVERAGE(E32:I32) -> 0.0077542897 | K32: =AVERAGE(F32:J32) -> 0.0073466688

Sheet Capex
B1: N-5 | C1: N-4 | D1: N-3 | E1: N-2 | F1: N-1 | G1: N | H1: N+1E | I1: N+2E | J1: N+3E | K1: N+4E | L1: N+5E
A2: Property, Plant and Equipment | B2: 2016 | C2: 2017 | D2: 2018 | E2: 2019 | F2: 2020 | G2: 2021 | H2: 2022 | I2: 2023 | J2: 2024 | K2: 2025 | L2: 2026
A3: Gross value | B3: 2.741385e+09 | C3: 2.6729884e+09 | D3: 2.6548523e+09 | E3: 2.3329147e+09 | F3: 2.1377079e+09 | G3: 2.1283684e+09 | H3: =H4+H5 -> 2.0307546e+09 | I3: =I4+I5 -> 2.0214463e+09 | J3: =J4+J5 -> 1.8351635e+09 | K3: =K4+K5 -> 1.7989233e+09 | L3: =L4+L5 -> 1.7530446e+09
A4: Accumulated depreciation | B4: =B3-B5 -> 7.7331993e+08 | C4: =C3-C5 -> 8.3623865e+08 | D4: =D3-D5 -> 9.2553877e+08 | E4: =E3-E5 -> 9.1125951e+08 | F4: =F3-F5 -> 8.3340307e+08 | G4: =G3-G5 -> 8.9151078e+08 | H4: =G4+H6 -> 9.0631706e+08 | I4: =H4+I6 -> 9.1572203e+08 | J4: =I4+J6 -> 9.1582788e+08 | K4: =J4+K6 -> 9.1757286e+08 | L4: =K4+L6 -> 9.2929559e+08
A5: Net value | B5: =BS!B9 -> 1.9680651e+09 | C5: =BS!C9 -> 1.8367497e+09 | D5: =BS!D9 -> 1.7293135e+09 | E5: =BS!E9 -> 1.4216552e+09 | F5: =BS!F9 -> 1.3043049e+09 | G5: =BS!G9 -> 1.2368576e+09 | H5: =BS!H9 -> 1.1244375e+09 | I5: =BS!I9 -> 1.1057243e+09 | ... L5: =BS!L9 -> 8.2374905e+08
A6: Depreciation for the period | C6: =C4-B4 -> 62918719 | D6: =D4-C4 -> 89300124 | E6: =E4-D4 -> -14279259 | F6: =F4-E4 -> -77856438 | G6: =G4-F4 -> 58107711 | H6: =(H5+G5)/2*H7 -> 14806281 | I6: =(I5+H5)/2*I7 -> 9404965.1 | J6: =(J5+I5)/2*J7 -> 105848.97 | K6: =(K5+J5)/2*K7 -> 1744980.8 | L6: =(L5+K5)/2*L7 -> 11722728
A7: Depreciation rate | C7: =C6*2/(B5+C5) -> 0.03307321 | D7: =D6*2/(C5+D5) -> 0.050083309 | E7: =E6*2/(D5+E5) -> -0.0090634091 | F7: =F6*2/(E5+F5) -> -0.057122215 | G7: =G6*2/(F5+G5) -> 0.045733172 | H7: =AVERAGE(C7:G7) -> 0.012540813 | I7: =AVERAGE(D7:H7) -> 0.0084343341 | J7: =AVERAGE(E7:I7) -> 0.00010453909 | K7: =AVERAGE(F7:J7) -> 0.0019381287 | L7: =AVERAGE(G7:K7) -> 0.013750198
A8: Capex_PPE | H8: =H3-G3 -> -97613795 | I8: =I3-H3 -> -9308268 | J8: =J3-I3 -> -1.862828e+08 | K8: =K3-J3 -> -36240193 | L8: =L3-K3 -> -45878709
A11: Intangible assets | B11: N-5 | C11: N-4 | D11: N-3 | E11: N-2 | F11: N-1 | G11: N | H11: N+1E | I11: N+2E | J11: N+3E | K11: N+4E | L11: N+5E
A12: Gross value | B12: 4.4718175e+08 | C12: 4.0272861e+08 | D12: 3.9053423e+08 | E12: 3.5357927e+08 | F12: 3.3963422e+08 | G12: 340095346 | H12: =H13+H14 -> 3.2832166e+08 | I12: =I13+I14 -> 3.3061538e+08 | J12: =J13+J14 -> 3.0813288e+08 | K12: =K13+K14 -> 3.0703452e+08 | L12: =L13+L14 -> 3.0311717e+08
A13: Accumulated amortization | B13: =B12-B14 -> 78643585 | C13: =C12-C14 -> 1.3172386e+08 | D13: =D12-D14 -> 1.3941523e+08 | E13: =E12-E14 -> 1.38756e+08 | F13: =F12-F14 -> 1.4444442e+08 | G13: =G12-G14 -> 1.5174308e+08 | H13: =G13+H15 -> 1.6093652e+08 | I13: =H13+I15 -> 1.6572545e+08 | J13: =I13+J15 -> 1.7007245e+08 | K13: =J13+K15 -> 1.74803e+08 | L13: =K13+L15 -> 1.7946701e+08
A14: Net value | B14: =BS!B10 -> 3.6853816e+08 | C14: =BS!C10 -> 2.7100475e+08 | D14: =BS!D10 -> 2.5111901e+08 | E14: =BS!E10 -> 2.1482327e+08 | F14: =BS!F10 -> 1.951898e+08 | G14: =BS!G10 -> 1.8835227e+08 | H14: =BS!H10 -> 1.6738515e+08 | I14: =BS!I10 -> 1.6488993e+08 | ... L14: =BS!L10 -> 1.2365016e+08
A15: Amortization for the period | C15: =C13-B13 -> 53080270 | D15: =D13-C13 -> 7691372.7 | E15: =E13-D13 -> -659224.5 | F15: =F13-E13 -> 5688415.5 | G15: =G13-F13 -> 7298657.7 | H15: =(H14+G14)/2*H16 -> 9193441.1 | I15: =(I14+H14)/2*I16 -> 4788935.1 | J15: =(J14+I14)/2*J16 -> 4347000.3 | K15: =(K14+J14)/2*K16 -> 4730549.1 | L15: =(L14+K14)/2*L16 -> 4664007.9
A16: Amortization rate | C16: =C15*2/(B14+C14) -> 0.1659944 | D16: =D15*2/(C14+D14) -> 0.029461876 | E16: =E15*2/(D14+E14) -> -0.0028296402 | F16: =F15*2/(E14+F14) -> 0.027747484 | G16: =G15*2/(F14+G14) -> 0.038059229 | H16: =AVERAGE(C16:G16) -> 0.05168667 | I16: =AVERAGE(D16:H16) -> 0.028825124 | J16: =AVERAGE(E16:I16) -> 0.028697773 | K16: =AVERAGE(F16:J16) -> 0.035003256 | L16: =AVERAGE(G16:K16) -> 0.03645441
A17: Capex_Intangible assets | H17: =H12-G12 -> -11773682 | I17: =I12-H12 -> 2293718.4 | J17: =J12-I12 -> -22482503 | K17: =K12-J12 -> -1098358.7 | L17: =L12-K12 -> -3917347.7

Sheet FCFF
B1: N+1E | C1: N+2E | D1: N+3E | E1: N+4E | F1: N+5E
B2: 2022 | C2: 2023 | D2: 2024 | E2: 2025 | F2: 2026
A3: Net profit | B3: =IS!H19 -> -9.3150979e+08 | C3: =IS!I19 -> -1.0135822e+09 | D3: =IS!J19 -> -1.0003473e+09 | E3: =IS!K19 -> -1.0790362e+09 | F3: =IS!L19 -> -9.2258556e+08
A4: +Net Financial expense*(1-tax rate)) | B4: =IS!H13*(1-Assumption!G11) -> 2.7903137e+08 | C4: =IS!I13*(1-Assumption!H11) -> 3.0536598e+08 | D4: =IS!J13*(1-Assumption!I11) -> 2.7519128e+08 | E4: =IS!K13*(1-Assumption!J11) -> 2.8883431e+08 | F4: =IS!L13*(1-Assumption!K11) -> 2.7261317e+08
A5: + Depreciation and Amortization | B5: =Capex!H6+Capex!H15 -> 23999722 | C5: =Capex!I6+Capex!I15 -> 14193900 | D5: =Capex!J6+Capex!J15 -> 4452849.3 | E5: =Capex!K6+Capex!K15 -> 6475529.8 | F5: =Capex!L6+Capex!L15 -> 16386736
A6: - Investment income | B6: =IS!H6 -> 43128681 | C6: =IS!I6 -> 34761501 | D6: =IS!J6 -> 24023842 | E6: =IS!K6 -> 38931008 | F6: =IS!L6 -> 33841585
A7: + impairment losses | B7: =IS!H7 -> 3.9951669e+08 | C7: =IS!I7 -> 4.5912751e+08 | D7: =IS!J7 -> 4.4783132e+08 | E7: =IS!K7 -> 4.7441501e+08 | F7: =IS!L7 -> 4.4245012e+08
A8: - Gains/(Loss) from fair value changes | B8: =IS!H8 -> 0 | C8: =IS!I8 -> 0 | D8: =IS!J8 -> 0 | E8: =IS!K8 -> 0 | F8: =IS!L8 -> 0
A9: - Gains/(Loss) on disposal of assets | B9: =IS!H9 -> 3955459 | C9: =IS!I9 -> 4191932.5 | D9: =IS!J9 -> 4646331.6 | E9: =IS!K9 -> 4993273 | F9: =IS!L9 -> 3186298.9
A10: - Non-operating income/(expense) | B10: =IS!H16 -> -8073660.4 | C10: =IS!I16 -> -8477455 | D10: =IS!J16 -> -7669574.3 | E10: =IS!K16 -> -5014147.9 | F10: =IS!L16 -> -5050592.3
A11: - Changes in Notes and accounts receivable | B11: =(BS!H4-BS!G4) -> -20755802 | C11: =(BS!I4-BS!H4) -> 73246435 | D11: =(BS!J4-BS!I4) -> -8.3938215e+08 | E11: =(BS!K4-BS!J4) -> -2.1701975e+08 | F11: =(BS!L4-BS!K4) -> -3.2765817e+08
A12: - Changes in Inventory | B12: =BS!H5-BS!G5 -> 1.2265823e+09 | C12: =BS!I5-BS!H5 -> -3.3844906e+08 | D12: =BS!J5-BS!I5 -> -8.6486445e+08 | E12: =BS!K5-BS!J5 -> -76825626 | F12: =BS!L5-BS!K5 -> -24858214
A13: + Notes and accounts payable | B13: =BS!H16-BS!G16 -> -2.7273355e+09 | C13: =BS!I16-BS!H16 -> 3.2982513e+08 | D13: =BS!J16-BS!I16 -> -7.108473e+08 | E13: =BS!K16-BS!J16 -> -3.2649101e+08 | F13: =BS!L16-BS!K16 -> -4.8839048e+08
A14: - Capital Expenditure | B14: =Capex!H8+Capex!H17 -> -1.0938748e+08 | C14: =Capex!I8+Capex!I17 -> -7014549.6 | D14: =Capex!J8+Capex!J17 -> -2.087653e+08 | E14: =Capex!K8+Capex!K17 -> -37338552 | F14: =Capex!L8+Capex!L17 -> -49796057
A15: Free cash flow the firm (FCFF) | B15: =B3+B4+B5-B6+B7-B8-B9-B10-B11-B12+B13-B14 -> -4.091747e+09 | C15: =C3+C4+C5-C6+C7-C8-C9-C10-C11-C12+C13-C14 -> 3.3667153e+08 | D15: =D3+D4+D5-D6+D7-D8-D9-D10-D11-D12+D13-D14 -> 9.0829219e+08 | E15: =E3+E4+E5-E6+E7-E8-E9-E10-E11-E12+E13-E14 -> -3.4352854e+08 | F15: =F3+F4+F5-F6+F7-F8-F9-F10-F11-F12+F13-F14 -> -3.0919086e+08

Sheet Beta
A1: year | B1: month | C1: Date | D1: company | E1: CSI300 | H1: CSI300 | J1: Beta | K1: =LINEST(Beta!G3:G72,Beta!H3:H72,TRUE) -> 0.62016634
A2: N-5 | B2: 1 | C2: 42398 | D2: 6.67 | E2: 2946.09
A3: N-5 | B3: 2 | C3: 42429 | D3: 6.25 | E3: 2877.467 | G3: =D3/D2-1 -> -0.062968516 | H3: =E3/E2-1 -> -0.023292907
A4: N-5 | B4: 3 | C4: 42460 | D4: 7.76 | E4: 3218.088 | G4: =D4/D3-1 -> 0.2416 | H4: =E4/E3-1 -> 0.11837529
A5: N-5 | B5: 4 | C5: 42489 | D5: 8.38 | E5: 3156.745 | G5: =D5/D4-1 -> 0.079896907 | H5: =E5/E4-1 -> -0.01906194
A6: N-5 | B6: 5 | C6: 42521 | D6: 7.42 | E6: 3169.56 | G6: =D6/D5-1 -> -0.11455847 | H6: =E6/E5-1 -> 0.0040595614
A7: N-5 | B7: 6 | C7: 42551 | D7: 7.7 | E7: 3153.921 | G7: =D7/D6-1 -> 0.037735849 | H7: =E7/E6-1 -> -0.0049341233
A8: N-5 | B8: 7 | C8: 42580 | D8: 7.28 | E8: 3203.93 | G8: =D8/D7-1 -> -0.054545455 | H8: =E8/E7-1 -> 0.015856136
A9: N-5 | B9: 8 | C9: 42613 | D9: 7.86 | E9: 3327.794 | G9: =D9/D8-1 -> 0.07967033 | H9: =E9/E8-1 -> 0.038660021
A10: N-5 | B10: 9 | C10: 42615 | D10: 7.84 | E10: 3314.114 | G10: =D10/D9-1 -> -0.0025445293 | H10: =E10/E9-1 -> -0.0041108314
A11: N-5 | B11: 11 | C11: 42704 | D11: 9.68 | E11: 3538.001 | G11: =D11/D10-1 -> 0.23469388 | H11: =E11/E10-1 -> 0.067555612
A12: N-5 | B12: 12 | C12: 42734 | D12: 10 | E12: 3310.081 | G12: =D12/D11-1 -> 0.033057851 | H12: =E12/E11-1 -> -0.064420558
A13: N-4 | B13: 1 | C13: 42761 | D13: 10.62 | E13: 3387.961 | G13: =D13/D12-1 -> 0.062 | H13: =E13/E12-1 -> 0.023528125
A14: N-4 | B14: 2 | C14: 42794 | D14: 11.62 | E14: 3452.81 | G14: =D14/D13-1 -> 0.094161959 | H14: =E14/E13-1 -> 0.019141011
... A72: N | B72: 12 | C72: 44561 | D72: 4.74 | E72: 4940.373 | G72: =D72/D71-1 -> 0.11529412 | H72: =E72/E71-1 -> 0.022422686

Sheet DCF
A1: Discounted Cash Flow Model (DCF Model)
A2: Total shares at Latest reporting date | B2: =Cover!D4 -> 869375282 | C2: Share price at Latest reporting date | D2: =Cover!D3 -> 4.74
A3: To simplify, assume valuation date is latest reporting date
A6: Number of years in Second stage | B6: 10
A7: Growth rate in Second stage | B7: 0.035
A8: Long-term growth rate for third stage | B8: 0.01
A10: Assumption | B10: Rate | C10: Methodology
A11: Rf | B11: 0.025 | C11: 5-year Chinese government bonds yield rate
A12: β | B12: =Beta!K1 -> 0.62016634
A13: E(Rm) | B13: 0.065 | C13: CSI300 10-years compounded growth rate
A14: Re | B14: =B11+B12*(B13-B11) -> 0.049806654
A15: Rd | B15: =AVERAGE(Assumption!E31:F31) -> 0.05435859
A16: E | B16: =D2*B2 -> 4.1208388e+09 | C16: Total shares at Latest reporting date*Share price at Latest reporting date
A17: D | B17: =BS!G15+BS!G20 -> 8425300000 | C17: (Short-term debt+Long-term debt) at Latest reporting date
A18: WACC | B18: =(B14*B16+B15*B17*(1-B19))/(B16+B17) -> 0.050701339
A19: Tax rate | B19: =AVERAGE(Assumption!B11:F11) -> 0.059229968
B21: N+1E | C21: N+2E | D21: N+3E | E21: N+4E | F21: N+5E
A22: First stage | B22: 2022 | C22: 2023 | D22: 2024 | E22: 2025 | F22: 2026
A23: FCFF | B23: =FCFF!B15 -> -4.091747e+09 | C23: =FCFF!C15 -> 3.3667153e+08 | D23: =FCFF!D15 -> 9.0829219e+08 | E23: =FCFF!E15 -> -3.4352854e+08 | F23: =FCFF!F15 -> -3.0919086e+08
B25: N+6E | C25: N+7E | D25: N+8E | E25: N+9E | F25: N+10E | G25: N+11E | H25: N+12E | I25: N+13E | J25: N+14E | K25: N+15E
A26: Second stage | B26: 2027 | C26: 2028 | D26: 2029 | E26: 2030 | F26: 2031 | G26: 2032 | H26: 2033 | I26: 2034 | J26: 2035 | K26: 2036
A27: FCFF | B27: =F23*(1+$B$7) -> -3.2001254e+08 | C27: =B27*(1+$B$7) -> -3.3121298e+08 | D27: =C27*(1+$B$7) -> -3.4280543e+08 | E27: =D27*(1+$B$7) -> -3.5480362e+08 | F27: =E27*(1+$B$7) -> -3.6722175e+08 | G27: =F27*(1+$B$7) -> -3.8007451e+08 | H27: =G27*(1+$B$7) -> -3.9337712e+08 | I27: =H27*(1+$B$7) -> -4.0714532e+08 | J27: =I27*(1+$B$7) -> -4.2139541e+08 | K27: =J27*(1+$B$7) -> -4.3614424e+08
B29: Discounted FCFF
A30: First stage | B30: =(NPV(B18,B23:F23)) -> -3.3296101e+09
A31: Second stage | B31: =((NPV(B18,B27:K27))/(1+B18)^5) -> -2.2247034e+09
A32: Third stage (Termination value) | B32: =(K27*(1+B8)*(1+B18)/(B18-B8)/(1+B18)^15) -> -5.4154284e+09
A33: Enterprise Value | B33: =SUM(B30:B32) -> -1.0969742e+10
A34: + Cash at latest reporting date | B34: =BS!G3 -> 1.4634375e+09
A35: －Minority interests at latest reporting date | B35: =BS!G26 -> 4.2696555e+08
A36: －(Short-term debt + Long-term debt) | B36: =(BS!G20+BS!G15) -> 8425300000
A37: =Value to shareholders of the company | B37: =B33+B34-B35-B36 -> -1.835857e+10
A38: Total shares | B38: =B2 -> 869375282
A39: Value per share | B39: =B37/B38 -> -21.116968
A42: Sensitivity test | B42: Long-term growth rate
A43: WACC | B43: =C43-0.5% -> 0 | C43: =D43-0.5% -> 0.005 | D43: =INT(B8*100+0.5)/100 -> 0.01 | E43: =D43+0.5% -> 0.015 | F43: =E43+0.5% -> 0.02 | G43: =F43+0.5% -> 0.025 | H43: =G43+0.5% -> 0.03 | I43: =H43+0.5% -> 0.035 | J43: =I43+0.5% -> 0.04
A44: =A45-0.5% -> 0.025 | B44: =((NPV($A$44,$B$23:$F$23)+(NPV($A$44,$B$27:$K$27))/(1+$A$44)^5+$K$27*(1+B43)/($A$44-B43)/(1+$A$44)^15)+$B$34-$B$35-$B$36)/$B$2 -> -29.597002 | C44: =((NPV($A$44,$B$23:$F$23)+(NPV($A$44,$B$27:$K$27))/(1+$A$44)^5+$K$27*(1+C43)/($A$44-C43)/(1+$A$44)^15)+$B$34-$B$35-$B$36)/$B$2 -> -33.147496 | D44: =((NPV($A$44,$B$23:$F$23)+(NPV($A$44,$B$27:$K$27))/(1+$A$44)^5+$K$27*(1+D43)/($A$44-D43)/(1+$A$44)^15)+$B$34-$B$35-$B$36)/$B$2 -> -39.064985 | E44: =((NPV($A$44,$B$23:$F$23)+(NPV($A$44,$B$27:$K$27))/(1+$A$44)^5+$K$27*(1+E43)/($A$44-E43)/(1+$A$44)^15)+$B$34-$B$35-$B$36)/$B$2 -> -50.899964 | F44: =((NPV($A$44,$B$23:$F$23)+(NPV($A$44,$B$27:$K$27))/(1+$A$44)^5+$K$27*(1+F43)/($A$44-F43)/(1+$A$44)^15)+$B$34-$B$35-$B$36)/$B$2 -> -86.404901 | G44: =((NPV($A$44,$B$23:$F$23)+(NPV($A$44,$B$27:$K$27))/(1+$A$44)^5+$K$27*(1+G43)/($A$44-G43)/(1+$A$44)^15)+$B$34-$B$35-$B$36)/$B$2 -> -5.1168006e+16 | H44: =((NPV($A$44,$B$23:$F$23)+(NPV($A$44,$B$27:$K$27))/(1+$A$44)^5+$K$27*(1+H43)/($A$44-H43)/(1+$A$44)^15)+$B$34-$B$35-$B$36)/$B$2 -> 55.614846 | I44: =((NPV($A$44,$B$23:$F$23)+(NPV($A$44,$B$27:$K$27))/(1+$A$44)^5+$K$27*(1+I43)/($A$44-I43)/(1+$A$44)^15)+$B$34-$B$35-$B$36)/$B$2 -> 20.109909 | J44: =((NPV($A$44,$B$23:$F$23)+(NPV($A$44,$B$27:$K$27))/(1+$A$44)^5+$K$27*(1+J43)/($A$44-J43)/(1+$A$44)^15)+$B$34-$B$35-$B$36)/$B$2 -> 8.2749304
A45: =A46-0.5% -> 0.03 | B45: =((NPV($A$45,$B$23:$F$23)+(NPV($A$45,$B$27:$K$27))/(1+$A$45)^5+$K$27*(1+B43)/($A$45-B43)/(1+$A$45)^15)+$B$34-$B$35-$B$36)/$B$2 -> -26.289696 | C45: =((NPV($A$45,$B$23:$F$23)+(NPV($A$45,$B$27:$K$27))/(1+$A$45)^5+$K$27*(1+C43)/($A$45-C43)/(1+$A$45)^15)+$B$34-$B$35-$B$36)/$B$2 -> -28.500807 | D45: =((NPV($A$45,$B$23:$F$23)+(NPV($A$45,$B$27:$K$27))/(1+$A$45)^5+$K$27*(1+D43)/($A$45-D43)/(1+$A$45)^15)+$B$34-$B$35-$B$36)/$B$2 -> -31.817472 | E45: =((NPV($A$45,$B$23:$F$23)+(NPV($A$45,$B$27:$K$27))/(1+$A$45)^5+$K$27*(1+E43)/($A$45-E43)/(1+$A$45)^15)+$B$34-$B$35-$B$36)/$B$2 -> -37.345249 | F45: =((NPV($A$45,$B$23:$F$23)+(NPV($A$45,$B$27:$K$27))/(1+$A$45)^5+$K$27*(1+F43)/($A$45-F43)/(1+$A$45)^15)+$B$34-$B$35-$B$36)/$B$2 -> -48.400801 | G45: =((NPV($A$45,$B$23:$F$23)+(NPV($A$45,$B$27:$K$27))/(1+$A$45)^5+$K$27*(1+G43)/($A$45-G43)/(1+$A$45)^15)+$B$34-$B$35-$B$36)/$B$2 -> -81.567459 | H45: =((NPV($A$45,$B$23:$F$23)+(NPV($A$45,$B$27:$K$27))/(1+$A$45)^5+$K$27*(1+H43)/($A$45-H43)/(1+$A$45)^15)+$B$34-$B$35-$B$36)/$B$2 -> -4.7798192e+16 | I45: =((NPV($A$45,$B$23:$F$23)+(NPV($A$45,$B$27:$K$27))/(1+$A$45)^5+$K$27*(1+I43)/($A$45-I43)/(1+$A$45)^15)+$B$34-$B$35-$B$36)/$B$2 -> 51.099173 | J45: =((NPV($A$45,$B$23:$F$23)+(NPV($A$45,$B$27:$K$27))/(1+$A$45)^5+$K$27*(1+J43)/($A$45-J43)/(1+$A$45)^15)+$B$34-$B$35-$B$36)/$B$2 -> 17.932515
A46: =A47-0.5% -> 0.035 | B46: =((NPV($A$46,$B$23:$F$23)+(NPV($A$46,$B$27:$K$27))/(1+$A$46)^5+$K$27*(1+B43)/($A$46-B43)/(1+$A$46)^15)+$B$34-$B$35-$B$36)/$B$2 -> -23.936388 | C46: =((NPV($A$46,$B$23:$F$23)+(NPV($A$46,$B$27:$K$27))/(1+$A$46)^5+$K$27*(1+C43)/($A$46-C43)/(1+$A$46)^15)+$B$34-$B$35-$B$36)/$B$2 -> -25.412226 | D46: =((NPV($A$46,$B$23:$F$23)+(NPV($A$46,$B$27:$K$27))/(1+$A$46)^5+$K$27*(1+D43)/($A$46-D43)/(1+$A$46)^15)+$B$34-$B$35-$B$36)/$B$2 -> -27.478399 | E46: =((NPV($A$46,$B$23:$F$23)+(NPV($A$46,$B$27:$K$27))/(1+$A$46)^5+$K$27*(1+E43)/($A$46-E43)/(1+$A$46)^15)+$B$34-$B$35-$B$36)/$B$2 -> -30.577659 | F46: =((NPV($A$46,$B$23:$F$23)+(NPV($A$46,$B$27:$K$27))/(1+$A$46)^5+$K$27*(1+F43)/($A$46-F43)/(1+$A$46)^15)+$B$34-$B$35-$B$36)/$B$2 -> -35.743092 | G46: =((NPV($A$46,$B$23:$F$23)+(NPV($A$46,$B$27:$K$27))/(1+$A$46)^5+$K$27*(1+G43)/($A$46-G43)/(1+$A$46)^15)+$B$34-$B$35-$B$36)/$B$2 -> -46.073957 | H46: =((NPV($A$46,$B$23:$F$23)+(NPV($A$46,$B$27:$K$27))/(1+$A$46)^5+$K$27*(1+H43)/($A$46-H43)/(1+$A$46)^15)+$B$34-$B$35-$B$36)/$B$2 -> -77.066553 | I46: =((NPV($A$46,$B$23:$F$23)+(NPV($A$46,$B$27:$K$27))/(1+$A$46)^5+$K$27*(1+I43)/($A$46-I43)/(1+$A$46)^15)+$B$34-$B$35-$B$36)/$B$2 -> -4.4665039e+16 | J46: =((NPV($A$46,$B$23:$F$23)+(NPV($A$46,$B$27:$K$27))/(1+$A$46)^5+$K$27*(1+J43)/($A$46-J43)/(1+$A$46)^15)+$B$34-$B$35-$B$36)/$B$2 -> 46.903832
A47: =A48-0.5% -> 0.04 | B47: =((NPV($A$47,$B$23:$F$23)+(NPV($A$47,$B$27:$K$27))/(1+$A$47)^5+$K$27*(1+B43)/($A$47-B43)/(1+$A$47)^15)+$B$34-$B$35-$B$36)/$B$2 -> -22.178814 | C47: =((NPV($A$47,$B$23:$F$23)+(NPV($A$47,$B$27:$K$27))/(1+$A$47)^5+$K$27*(1+C43)/($A$47-C43)/(1+$A$47)^15)+$B$34-$B$35-$B$36)/$B$2 -> -23.213475 | D47: =((NPV($A$47,$B$23:$F$23)+(NPV($A$47,$B$27:$K$27))/(1+$A$47)^5+$K$27*(1+D43)/($A$47-D43)/(1+$A$47)^15)+$B$34-$B$35-$B$36)/$B$2 -> -24.593023 | E47: =((NPV($A$47,$B$23:$F$23)+(NPV($A$47,$B$27:$K$27))/(1+$A$47)^5+$K$27*(1+E43)/($A$47-E43)/(1+$A$47)^15)+$B$34-$B$35-$B$36)/$B$2 -> -26.52439 | F47: =((NPV($A$47,$B$23:$F$23)+(NPV($A$47,$B$27:$K$27))/(1+$A$47)^5+$K$27*(1+F43)/($A$47-F43)/(1+$A$47)^15)+$B$34-$B$35-$B$36)/$B$2 -> -29.421441 | G47: =((NPV($A$47,$B$23:$F$23)+(NPV($A$47,$B$27:$K$27))/(1+$A$47)^5+$K$27*(1+G43)/($A$47-G43)/(1+$A$47)^15)+$B$34-$B$35-$B$36)/$B$2 -> -34.249859 | H47: =((NPV($A$47,$B$23:$F$23)+(NPV($A$47,$B$27:$K$27))/(1+$A$47)^5+$K$27*(1+H43)/($A$47-H43)/(1+$A$47)^15)+$B$34-$B$35-$B$36)/$B$2 -> -43.906695 | I47: =((NPV($A$47,$B$23:$F$23)+(NPV($A$47,$B$27:$K$27))/(1+$A$47)^5+$K$27*(1+I43)/($A$47-I43)/(1+$A$47)^15)+$B$34-$B$35-$B$36)/$B$2 -> -72.877202 | J47: =((NPV($A$47,$B$23:$F$23)+(NPV($A$47,$B$27:$K$27))/(1+$A$47)^5+$K$27*(1+J43)/($A$47-J43)/(1+$A$47)^15)+$B$34-$B$35-$B$36)/$B$2 -> -4.1750902e+16
A48: =A49-0.5% -> 0.045 | B48: =((NPV($A$48,$B$23:$F$23)+(NPV($A$48,$B$27:$K$27))/(1+$A$48)^5+$K$27*(1+B43)/($A$48-B43)/(1+$A$48)^15)+$B$34-$B$35-$B$36)/$B$2 -> -20.817965 | C48: =((NPV($A$48,$B$23:$F$23)+(NPV($A$48,$B$27:$K$27))/(1+$A$48)^5+$K$27*(1+C43)/($A$48-C43)/(1+$A$48)^15)+$B$34-$B$35-$B$36)/$B$2 -> -21.57044 | D48: =((NPV($A$48,$B$23:$F$23)+(NPV($A$48,$B$27:$K$27))/(1+$A$48)^5+$K$27*(1+D43)/($A$48-D43)/(1+$A$48)^15)+$B$34-$B$35-$B$36)/$B$2 -> -22.537909 | E48: =((NPV($A$48,$B$23:$F$23)+(NPV($A$48,$B$27:$K$27))/(1+$A$48)^5+$K$27*(1+E43)/($A$48-E43)/(1+$A$48)^15)+$B$34-$B$35-$B$36)/$B$2 -> -23.827867 | F48: =((NPV($A$48,$B$23:$F$23)+(NPV($A$48,$B$27:$K$27))/(1+$A$48)^5+$K$27*(1+F43)/($A$48-F43)/(1+$A$48)^15)+$B$34-$B$35-$B$36)/$B$2 -> -25.633807 | G48: =((NPV($A$48,$B$23:$F$23)+(NPV($A$48,$B$27:$K$27))/(1+$A$48)^5+$K$27*(1+G43)/($A$48-G43)/(1+$A$48)^15)+$B$34-$B$35-$B$36)/$B$2 -> -28.342719 | H48: =((NPV($A$48,$B$23:$F$23)+(NPV($A$48,$B$27:$K$27))/(1+$A$48)^5+$K$27*(1+H43)/($A$48-H43)/(1+$A$48)^15)+$B$34-$B$35-$B$36)/$B$2 -> -32.857571 | I48: =((NPV($A$48,$B$23:$F$23)+(NPV($A$48,$B$27:$K$27))/(1+$A$48)^5+$K$27*(1+I43)/($A$48-I43)/(1+$A$48)^15)+$B$34-$B$35-$B$36)/$B$2 -> -41.887276 | J48: =((NPV($A$48,$B$23:$F$23)+(NPV($A$48,$B$27:$K$27))/(1+$A$48)^5+$K$27*(1+J43)/($A$48-J43)/(1+$A$48)^15)+$B$34-$B$35-$B$36)/$B$2 -> -68.976389
...

Sheet Reference
